2025-03-18 01:01:39 | InsiderCrypto | INFO | test_logger:16 - Esta é uma mensagem de INFO
2025-03-18 01:01:39 | InsiderCrypto | WARNING | test_logger:17 - Esta é uma mensagem de WARNING
2025-03-18 01:01:39 | InsiderCrypto | ALERT | log_config:32 - Esta é uma mensagem de ALERT
2025-03-18 01:01:39 | InsiderCrypto | ERROR | test_logger:19 - Esta é uma mensagem de ERROR
2025-03-18 01:01:39 | InsiderCrypto | CRITICAL | test_logger:20 - Esta é uma mensagem de CRITICAL
2025-03-18 01:01:39 | InsiderCrypto | ERROR | test_logger:26 - Erro ao dividir por zero: division by zero
Traceback (most recent call last):
  File "D:\Workspace\Projeto-Python\insider_crypto_bot\tests\test_logger.py", line 24, in <module>
    1 / 0  # Gera uma exceção
    ~~^~~
ZeroDivisionError: division by zero
2025-03-18 01:51:03 | InsiderCrypto | INFO | test_logger:16 - Esta é uma mensagem de INFO
2025-03-18 01:51:03 | InsiderCrypto | WARNING | test_logger:17 - Esta é uma mensagem de WARNING
2025-03-18 01:51:03 | InsiderCrypto | ALERT | log_config:33 - Esta é uma mensagem de ALERT
2025-03-18 01:51:03 | InsiderCrypto | ERROR | test_logger:19 - Esta é uma mensagem de ERROR
2025-03-18 01:51:03 | InsiderCrypto | CRITICAL | test_logger:20 - Esta é uma mensagem de CRITICAL
2025-03-18 01:51:03 | InsiderCrypto | ERROR | test_logger:26 - Erro ao dividir por zero: division by zero
Traceback (most recent call last):
  File "D:\Workspace\Projeto-Python\insider_crypto_bot\tests\test_logger.py", line 24, in <module>
    1 / 0  # Gera uma exceção
    ~~^~~
ZeroDivisionError: division by zero
2025-03-18 01:59:01 | InsiderCrypto | INFO | test_logger:16 - Esta é uma mensagem de INFO
2025-03-18 01:59:01 | InsiderCrypto | WARNING | test_logger:17 - Esta é uma mensagem de WARNING
2025-03-18 01:59:01 | InsiderCrypto | ALERT | log_config:33 - Esta é uma mensagem de ALERT
2025-03-18 01:59:01 | InsiderCrypto | ERROR | test_logger:19 - Esta é uma mensagem de ERROR
2025-03-18 01:59:01 | InsiderCrypto | CRITICAL | test_logger:20 - Esta é uma mensagem de CRITICAL
2025-03-18 01:59:01 | InsiderCrypto | ERROR | test_logger:26 - Erro ao dividir por zero: division by zero
Traceback (most recent call last):
  File "D:\Workspace\Projeto-Python\insider_crypto_bot\tests\test_logger.py", line 24, in <module>
    1 / 0  # Gera uma exceção
    ~~^~~
ZeroDivisionError: division by zero
2025-03-18 01:59:20 | InsiderCrypto | INFO | test_logger:16 - Esta é uma mensagem de INFO
2025-03-18 01:59:20 | InsiderCrypto | WARNING | test_logger:17 - Esta é uma mensagem de WARNING
2025-03-18 01:59:20 | InsiderCrypto | ALERT | log_config:33 - Esta é uma mensagem de ALERT
2025-03-18 01:59:20 | InsiderCrypto | ERROR | test_logger:19 - Esta é uma mensagem de ERROR
2025-03-18 01:59:20 | InsiderCrypto | CRITICAL | test_logger:20 - Esta é uma mensagem de CRITICAL
2025-03-18 01:59:20 | InsiderCrypto | ERROR | test_logger:26 - Erro ao dividir por zero: division by zero
Traceback (most recent call last):
  File "D:\Workspace\Projeto-Python\insider_crypto_bot\tests\test_logger.py", line 24, in <module>
    1 / 0  # Gera uma exceção
    ~~^~~
ZeroDivisionError: division by zero
2025-03-18 02:04:07 | InsiderCrypto | INFO | test_logger:16 - Esta é uma mensagem de INFO
2025-03-18 02:04:07 | InsiderCrypto | WARNING | test_logger:17 - Esta é uma mensagem de WARNING
2025-03-18 02:04:07 | InsiderCrypto | ALERT | log_config:33 - Esta é uma mensagem de ALERT
2025-03-18 02:04:07 | InsiderCrypto | ERROR | test_logger:19 - Esta é uma mensagem de ERROR
2025-03-18 02:04:07 | InsiderCrypto | CRITICAL | test_logger:20 - Esta é uma mensagem de CRITICAL
2025-03-18 02:04:07 | InsiderCrypto | ERROR | test_logger:26 - Erro ao dividir por zero: division by zero
Traceback (most recent call last):
  File "D:\Workspace\Projeto-Python\insider_crypto_bot\tests\test_logger.py", line 24, in <module>
    1 / 0  # Gera uma exceção
    ~~^~~
ZeroDivisionError: division by zero
2025-03-18 02:21:27 | InsiderCrypto | DEBUG | test_logger:12 - Esta é uma mensagem de DEBUG
2025-03-18 02:21:27 | InsiderCrypto | INFO | test_logger:13 - Esta é uma mensagem de INFO
2025-03-18 02:21:27 | InsiderCrypto | WARNING | test_logger:14 - Esta é uma mensagem de WARNING
2025-03-18 02:21:27 | InsiderCrypto | ALERT | log_config:33 - Esta é uma mensagem de ALERT
2025-03-18 02:21:27 | InsiderCrypto | ERROR | test_logger:16 - Esta é uma mensagem de ERROR
2025-03-18 02:21:27 | InsiderCrypto | CRITICAL | test_logger:17 - Esta é uma mensagem de CRITICAL
2025-03-18 02:21:27 | InsiderCrypto | ERROR | test_logger:23 - Erro ao dividir por zero: division by zero
Traceback (most recent call last):
  File "D:\Workspace\Projeto-Python\insider_crypto_bot\tests\test_logger.py", line 21, in <module>
    1 / 0  # Gera uma exceção
    ~~^~~
ZeroDivisionError: division by zero
2025-03-18 02:26:25 | InsiderCrypto | DEBUG | test_logger:12 - Esta é uma mensagem de DEBUG
2025-03-18 02:26:25 | InsiderCrypto | INFO | test_logger:13 - Esta é uma mensagem de INFO
2025-03-18 02:26:25 | InsiderCrypto | WARNING | test_logger:14 - Esta é uma mensagem de WARNING
2025-03-18 02:26:25 | InsiderCrypto | ALERT | log_config:33 - Esta é uma mensagem de ALERT
2025-03-18 02:26:25 | InsiderCrypto | ERROR | test_logger:16 - Esta é uma mensagem de ERROR
2025-03-18 02:26:25 | InsiderCrypto | CRITICAL | test_logger:17 - Esta é uma mensagem de CRITICAL
2025-03-18 02:26:25 | InsiderCrypto | ERROR | test_logger:23 - Erro ao dividir por zero: division by zero
Traceback (most recent call last):
  File "D:\Workspace\Projeto-Python\insider_crypto_bot\tests\test_logger.py", line 21, in <module>
    1 / 0  # Gera uma exceção
    ~~^~~
ZeroDivisionError: division by zero
2025-03-18 02:26:32 | InsiderCrypto | DEBUG | test_logger:12 - Esta é uma mensagem de DEBUG
2025-03-18 02:26:32 | InsiderCrypto | INFO | test_logger:13 - Esta é uma mensagem de INFO
2025-03-18 02:26:32 | InsiderCrypto | WARNING | test_logger:14 - Esta é uma mensagem de WARNING
2025-03-18 02:26:32 | InsiderCrypto | ALERT | log_config:33 - Esta é uma mensagem de ALERT
2025-03-18 02:26:32 | InsiderCrypto | ERROR | test_logger:16 - Esta é uma mensagem de ERROR
2025-03-18 02:26:32 | InsiderCrypto | CRITICAL | test_logger:17 - Esta é uma mensagem de CRITICAL
2025-03-18 02:26:32 | InsiderCrypto | ERROR | test_logger:23 - Erro ao dividir por zero: division by zero
Traceback (most recent call last):
  File "D:\Workspace\Projeto-Python\insider_crypto_bot\tests\test_logger.py", line 21, in <module>
    1 / 0  # Gera uma exceção
    ~~^~~
ZeroDivisionError: division by zero
2025-03-18 03:55:37 | InsiderCrypto | DEBUG | test_logger:9 - Esta é uma mensagem de DEBUG
2025-03-18 03:55:37 | InsiderCrypto | INFO | test_logger:10 - Esta é uma mensagem de INFO
2025-03-18 03:55:37 | InsiderCrypto | WARNING | test_logger:11 - Esta é uma mensagem de WARNING
2025-03-18 03:55:37 | InsiderCrypto | ALERT | log_config:33 - Esta é uma mensagem de ALERT
2025-03-18 03:55:37 | InsiderCrypto | ERROR | test_logger:13 - Esta é uma mensagem de ERROR
2025-03-18 03:55:37 | InsiderCrypto | CRITICAL | test_logger:14 - Esta é uma mensagem de CRITICAL
2025-03-18 03:55:37 | InsiderCrypto | ERROR | test_logger:20 - Erro ao dividir por zero: division by zero
Traceback (most recent call last):
  File "D:\Workspace\Projeto-Python\insider_crypto_bot\tests\test_logger.py", line 18, in <module>
    1 / 0  # Gera uma exceção
    ~~^~~
ZeroDivisionError: division by zero
2025-03-18 03:56:47 | InsiderCrypto | DEBUG | test_logger:9 - Esta é uma mensagem de DEBUG
2025-03-18 03:56:47 | InsiderCrypto | INFO | test_logger:10 - Esta é uma mensagem de INFO
2025-03-18 03:56:47 | InsiderCrypto | WARNING | test_logger:11 - Esta é uma mensagem de WARNING
2025-03-18 03:56:47 | InsiderCrypto | ALERT | log_config:33 - Esta é uma mensagem de ALERT
2025-03-18 03:56:47 | InsiderCrypto | ERROR | test_logger:13 - Esta é uma mensagem de ERROR
2025-03-18 03:56:47 | InsiderCrypto | CRITICAL | test_logger:14 - Esta é uma mensagem de CRITICAL
2025-03-18 03:56:47 | InsiderCrypto | ERROR | test_logger:20 - Erro ao dividir por zero: division by zero
Traceback (most recent call last):
  File "D:\Workspace\Projeto-Python\insider_crypto_bot\tests\test_logger.py", line 18, in <module>
    1 / 0  # Gera uma exceção
    ~~^~~
ZeroDivisionError: division by zero
2025-03-18 04:00:32 | InsiderCrypto | DEBUG | test_logger:9 - Esta é uma mensagem de DEBUG
2025-03-18 04:00:32 | InsiderCrypto | INFO | test_logger:10 - Esta é uma mensagem de INFO
2025-03-18 04:00:32 | InsiderCrypto | WARNING | test_logger:11 - Esta é uma mensagem de WARNING
2025-03-18 04:00:32 | InsiderCrypto | ALERT | log_config:33 - Esta é uma mensagem de ALERT
2025-03-18 04:00:32 | InsiderCrypto | ERROR | test_logger:13 - Esta é uma mensagem de ERROR
2025-03-18 04:00:32 | InsiderCrypto | CRITICAL | test_logger:14 - Esta é uma mensagem de CRITICAL
2025-03-18 04:00:32 | InsiderCrypto | ERROR | test_logger:20 - Erro ao dividir por zero: division by zero
Traceback (most recent call last):
  File "D:\Workspace\Projeto-Python\insider_crypto_bot\tests\test_logger.py", line 18, in <module>
    1 / 0  # Gera uma exceção
    ~~^~~
ZeroDivisionError: division by zero
2025-03-18 04:28:26 | InsiderCrypto | DEBUG | test_logger:20 - Esta é uma mensagem de DEBUG
2025-03-18 04:28:26 | InsiderCrypto | INFO | test_logger:21 - Esta é uma mensagem de INFO
2025-03-18 04:28:26 | InsiderCrypto | WARNING | test_logger:22 - Esta é uma mensagem de WARNING
2025-03-18 04:28:26 | InsiderCrypto | ALERT | log_config:33 - Esta é uma mensagem de ALERT
2025-03-18 04:28:26 | InsiderCrypto | ERROR | test_logger:24 - Esta é uma mensagem de ERROR
2025-03-18 04:28:26 | InsiderCrypto | CRITICAL | test_logger:25 - Esta é uma mensagem de CRITICAL
2025-03-18 04:28:26 | InsiderCrypto | ERROR | test_logger:31 - Erro ao dividir por zero: division by zero
Traceback (most recent call last):
  File "D:\Workspace\Projeto-Python\insider_crypto_bot\tests\test_logger.py", line 29, in test_logger
    1 / 0  # Gera uma exceção
    ~~^~~
ZeroDivisionError: division by zero
2025-03-18 04:32:31 | InsiderCrypto | DEBUG | test_logger:17 - Esta é uma mensagem de DEBUG
2025-03-18 04:32:31 | InsiderCrypto | INFO | test_logger:18 - Esta é uma mensagem de INFO
2025-03-18 04:32:31 | InsiderCrypto | WARNING | test_logger:19 - Esta é uma mensagem de WARNING
2025-03-18 04:32:31 | InsiderCrypto | ALERT | log_config:33 - Esta é uma mensagem de ALERT
2025-03-18 04:32:31 | InsiderCrypto | ERROR | test_logger:21 - Esta é uma mensagem de ERROR
2025-03-18 04:32:31 | InsiderCrypto | CRITICAL | test_logger:22 - Esta é uma mensagem de CRITICAL
2025-03-18 04:32:31 | InsiderCrypto | ERROR | test_logger:28 - Erro ao dividir por zero: division by zero
Traceback (most recent call last):
  File "D:\Workspace\Projeto-Python\insider_crypto_bot\tests\test_logger.py", line 26, in test_logger
    1 / 0  # Gera uma exceção
    ~~^~~
ZeroDivisionError: division by zero
2025-03-18 04:40:38 | InsiderCrypto | DEBUG | log_config:80 - Nível de log configurado: DEBUG (10)
2025-03-18 04:47:01 | InsiderCrypto | DEBUG | log_config:80 - Nível de log configurado: DEBUG (10)
2025-03-18 04:47:01 | InsiderCrypto | DEBUG | log_config:80 - Nível de log configurado: DEBUG (10)
2025-03-18 04:48:18 | InsiderCrypto | DEBUG | log_config:80 - Nível de log configurado: DEBUG (10)
2025-03-18 04:48:19 | InsiderCrypto | DEBUG | log_config:80 - Nível de log configurado: DEBUG (10)
2025-03-18 04:49:35 | InsiderCrypto | DEBUG | log_config:80 - Nível de log configurado: DEBUG (10)
2025-03-18 04:49:36 | InsiderCrypto | DEBUG | log_config:80 - Nível de log configurado: DEBUG (10)
2025-03-18 04:49:42 | InsiderCrypto | DEBUG | dex_api:27 - Dados de mercado obtidos para SOL
2025-03-18 04:57:29 | InsiderCrypto | DEBUG | log_config:80 - Nível de log configurado: DEBUG (10)
2025-03-18 04:57:30 | InsiderCrypto | DEBUG | log_config:80 - Nível de log configurado: DEBUG (10)
2025-03-18 04:59:39 | InsiderCrypto | DEBUG | log_config:80 - Nível de log configurado: DEBUG (10)
2025-03-18 04:59:39 | InsiderCrypto | DEBUG | log_config:80 - Nível de log configurado: DEBUG (10)
2025-03-18 05:04:30 | InsiderCrypto | DEBUG | log_config:80 - Nível de log configurado: DEBUG (10)
2025-03-18 05:04:31 | InsiderCrypto | DEBUG | log_config:80 - Nível de log configurado: DEBUG (10)
2025-03-18 05:07:42 | InsiderCrypto | DEBUG | log_config:80 - Nível de log configurado: DEBUG (10)
2025-03-18 05:07:43 | InsiderCrypto | DEBUG | log_config:80 - Nível de log configurado: DEBUG (10)
2025-03-18 05:10:11 | InsiderCrypto | DEBUG | log_config:80 - Nível de log configurado: DEBUG (10)
2025-03-18 05:10:11 | InsiderCrypto | DEBUG | log_config:80 - Nível de log configurado: DEBUG (10)
2025-03-18 05:13:21 | InsiderCrypto | DEBUG | log_config:80 - Nível de log configurado: DEBUG (10)
2025-03-18 05:13:22 | InsiderCrypto | DEBUG | log_config:80 - Nível de log configurado: DEBUG (10)
2025-03-18 15:06:41 | InsiderCrypto | DEBUG | log_config:80 - Nível de log configurado: DEBUG (10)
2025-03-18 15:06:42 | InsiderCrypto | DEBUG | log_config:80 - Nível de log configurado: DEBUG (10)
2025-03-18 15:07:07 | InsiderCrypto | DEBUG | log_config:80 - Nível de log configurado: DEBUG (10)
2025-03-18 15:07:08 | InsiderCrypto | DEBUG | log_config:80 - Nível de log configurado: DEBUG (10)
2025-03-18 15:08:07 | InsiderCrypto | DEBUG | test_logger:17 - Esta é uma mensagem de DEBUG
2025-03-18 15:08:07 | InsiderCrypto | INFO | test_logger:18 - Esta é uma mensagem de INFO
2025-03-18 15:08:07 | InsiderCrypto | WARNING | test_logger:19 - Esta é uma mensagem de WARNING
2025-03-18 15:08:07 | InsiderCrypto | ALERT | log_config:33 - Esta é uma mensagem de ALERT
2025-03-18 15:08:07 | InsiderCrypto | ERROR | test_logger:21 - Esta é uma mensagem de ERROR
2025-03-18 15:08:07 | InsiderCrypto | CRITICAL | test_logger:22 - Esta é uma mensagem de CRITICAL
2025-03-18 15:08:07 | InsiderCrypto | ERROR | test_logger:28 - Erro ao dividir por zero: division by zero
Traceback (most recent call last):
  File "D:\Workspace\Projeto-Python\insider_crypto_bot\tests\test_logger.py", line 26, in test_logger
    1 / 0  # Gera uma exceção
    ~~^~~
ZeroDivisionError: division by zero
2025-03-18 16:06:23 | InsiderCrypto | DEBUG | test_logger:18 - Esta é uma mensagem de DEBUG
2025-03-18 16:06:23 | InsiderCrypto | INFO | test_logger:19 - Esta é uma mensagem de INFO
2025-03-18 16:06:23 | InsiderCrypto | WARNING | test_logger:20 - Esta é uma mensagem de WARNING
2025-03-18 16:06:23 | InsiderCrypto | ALERT | log_config:41 - Esta é uma mensagem de ALERT
2025-03-18 16:06:23 | InsiderCrypto | ERROR | test_logger:22 - Esta é uma mensagem de ERROR
2025-03-18 16:06:23 | InsiderCrypto | CRITICAL | test_logger:23 - Esta é uma mensagem de CRITICAL
2025-03-18 16:06:23 | InsiderCrypto | ERROR | test_logger:29 - Erro ao dividir por zero: division by zero
Traceback (most recent call last):
  File "D:\Workspace\Projeto-Python\insider_crypto_bot\tests\test_logger.py", line 27, in test_logger
    1 / 0  # Gera uma exceção
    ~~^~~
ZeroDivisionError: division by zero
2025-03-18 16:06:23 | InsiderCrypto | ERROR | log_config:52 - [APIConnectionError] [APIConnectionError] Falha na conexão com a API (URL: https://api.example.com) | Detalhes: Timeout ao tentar conectar | Causa: Erro de rede
2025-03-18 16:06:23 | InsiderCrypto | INFO | test_logger:69 - Testando o logger retornado por get_logger
2025-03-18 16:06:28 | InsiderCrypto | DEBUG | test_logger:18 - Esta é uma mensagem de DEBUG
2025-03-18 16:06:28 | InsiderCrypto | INFO | test_logger:19 - Esta é uma mensagem de INFO
2025-03-18 16:06:28 | InsiderCrypto | WARNING | test_logger:20 - Esta é uma mensagem de WARNING
2025-03-18 16:06:28 | InsiderCrypto | ALERT | log_config:41 - Esta é uma mensagem de ALERT
2025-03-18 16:06:28 | InsiderCrypto | ERROR | test_logger:22 - Esta é uma mensagem de ERROR
2025-03-18 16:06:28 | InsiderCrypto | CRITICAL | test_logger:23 - Esta é uma mensagem de CRITICAL
2025-03-18 16:06:28 | InsiderCrypto | ERROR | test_logger:29 - Erro ao dividir por zero: division by zero
Traceback (most recent call last):
  File "D:\Workspace\Projeto-Python\insider_crypto_bot\tests\test_logger.py", line 27, in test_logger
    1 / 0  # Gera uma exceção
    ~~^~~
ZeroDivisionError: division by zero
2025-03-18 16:06:28 | InsiderCrypto | ERROR | log_config:52 - [APIConnectionError] [APIConnectionError] Falha na conexão com a API (URL: https://api.example.com) | Detalhes: Timeout ao tentar conectar | Causa: Erro de rede
2025-03-18 16:06:28 | InsiderCrypto | INFO | test_logger:69 - Testando o logger retornado por get_logger
2025-03-18 17:52:29 | InsiderCrypto | DEBUG | test_logger:18 - Esta é uma mensagem de DEBUG
2025-03-18 17:52:29 | InsiderCrypto | INFO | test_logger:19 - Esta é uma mensagem de INFO
2025-03-18 17:52:29 | InsiderCrypto | WARNING | test_logger:20 - Esta é uma mensagem de WARNING
2025-03-18 17:52:29 | InsiderCrypto | ALERT | log_config:42 - Esta é uma mensagem de ALERT
2025-03-18 17:52:29 | InsiderCrypto | ERROR | test_logger:22 - Esta é uma mensagem de ERROR
2025-03-18 17:52:29 | InsiderCrypto | CRITICAL | test_logger:23 - Esta é uma mensagem de CRITICAL
2025-03-18 17:52:29 | InsiderCrypto | ERROR | test_logger:29 - Erro ao dividir por zero: division by zero
Traceback (most recent call last):
  File "D:\Workspace\Projeto-Python\insider_crypto_bot\tests\test_logger.py", line 27, in test_logger
    1 / 0  # Gera uma exceção
    ~~^~~
ZeroDivisionError: division by zero
2025-03-18 17:52:29 | InsiderCrypto | ERROR | log_config:54 - [APIConnectionError] [APIConnectionError] Falha na conexão com a API (URL: https://api.example.com) | Detalhes: Timeout ao tentar conectar | Causa: Erro de rede
2025-03-18 17:52:29 | InsiderCrypto | INFO | test_logger:69 - Testando o logger retornado por get_logger
2025-03-18 18:14:15 | InsiderCrypto | DEBUG | test_logger:18 - Esta é uma mensagem de DEBUG
2025-03-18 18:14:15 | InsiderCrypto | INFO | test_logger:19 - Esta é uma mensagem de INFO
2025-03-18 18:14:15 | InsiderCrypto | WARNING | test_logger:20 - Esta é uma mensagem de WARNING
2025-03-18 18:14:15 | InsiderCrypto | ALERT | log_config:42 - Esta é uma mensagem de ALERT
2025-03-18 18:14:15 | InsiderCrypto | ERROR | test_logger:22 - Esta é uma mensagem de ERROR
2025-03-18 18:14:15 | InsiderCrypto | CRITICAL | test_logger:23 - Esta é uma mensagem de CRITICAL
2025-03-18 18:14:15 | InsiderCrypto | ERROR | test_logger:29 - Erro ao dividir por zero: division by zero
Traceback (most recent call last):
  File "D:\Workspace\Projeto-Python\insider_crypto_bot\tests\test_logger.py", line 27, in test_logger
    1 / 0  # Gera uma exceção
    ~~^~~
ZeroDivisionError: division by zero
2025-03-18 18:14:15 | InsiderCrypto | ERROR | log_config:53 - [APIConnectionError] [APIConnectionError] Falha na conexão com a API (URL: https://api.example.com) | Detalhes: Timeout ao tentar conectar | Causa: Erro de rede
2025-03-18 18:14:15 | InsiderCrypto | INFO | test_logger:69 - Testando o logger retornado por get_logger
2025-03-18 18:14:19 | InsiderCrypto | DEBUG | test_logger:18 - Esta é uma mensagem de DEBUG
2025-03-18 18:14:19 | InsiderCrypto | INFO | test_logger:19 - Esta é uma mensagem de INFO
2025-03-18 18:14:19 | InsiderCrypto | WARNING | test_logger:20 - Esta é uma mensagem de WARNING
2025-03-18 18:14:19 | InsiderCrypto | ALERT | log_config:42 - Esta é uma mensagem de ALERT
2025-03-18 18:14:19 | InsiderCrypto | ERROR | test_logger:22 - Esta é uma mensagem de ERROR
2025-03-18 18:14:19 | InsiderCrypto | CRITICAL | test_logger:23 - Esta é uma mensagem de CRITICAL
2025-03-18 18:14:19 | InsiderCrypto | ERROR | test_logger:29 - Erro ao dividir por zero: division by zero
Traceback (most recent call last):
  File "D:\Workspace\Projeto-Python\insider_crypto_bot\tests\test_logger.py", line 27, in test_logger
    1 / 0  # Gera uma exceção
    ~~^~~
ZeroDivisionError: division by zero
2025-03-18 18:14:19 | InsiderCrypto | ERROR | log_config:53 - [APIConnectionError] [APIConnectionError] Falha na conexão com a API (URL: https://api.example.com) | Detalhes: Timeout ao tentar conectar | Causa: Erro de rede
2025-03-18 18:14:19 | InsiderCrypto | INFO | test_logger:69 - Testando o logger retornado por get_logger
2025-03-18 20:36:47 | InsiderCrypto | DEBUG | test_logger:18 - Esta é uma mensagem de DEBUG
2025-03-18 20:36:47 | InsiderCrypto | INFO | test_logger:19 - Esta é uma mensagem de INFO
2025-03-18 20:36:47 | InsiderCrypto | WARNING | test_logger:20 - Esta é uma mensagem de WARNING
2025-03-18 20:36:47 | InsiderCrypto | ALERT | log_config:42 - Esta é uma mensagem de ALERT
2025-03-18 20:36:47 | InsiderCrypto | ERROR | test_logger:22 - Esta é uma mensagem de ERROR
2025-03-18 20:36:47 | InsiderCrypto | CRITICAL | test_logger:23 - Esta é uma mensagem de CRITICAL
2025-03-18 20:36:47 | InsiderCrypto | ERROR | test_logger:29 - Erro ao dividir por zero: division by zero
Traceback (most recent call last):
  File "D:\Workspace\Projeto-Python\insider_crypto_bot\tests\test_logger.py", line 27, in test_logger
    1 / 0  # Gera uma exceção
    ~~^~~
ZeroDivisionError: division by zero
2025-03-18 20:36:47 | InsiderCrypto | ERROR | log_config:53 - [APIConnectionError] [APIConnectionError] Falha na conexão com a API (URL: https://api.example.com) | Detalhes: Timeout ao tentar conectar | Causa: Erro de rede
2025-03-18 20:36:47 | InsiderCrypto | INFO | test_logger:69 - Testando o logger retornado por get_logger
2025-03-18 20:36:58 | InsiderCrypto | DEBUG | test_logger:18 - Esta é uma mensagem de DEBUG
2025-03-18 20:36:58 | InsiderCrypto | INFO | test_logger:19 - Esta é uma mensagem de INFO
2025-03-18 20:36:58 | InsiderCrypto | WARNING | test_logger:20 - Esta é uma mensagem de WARNING
2025-03-18 20:36:58 | InsiderCrypto | ALERT | log_config:42 - Esta é uma mensagem de ALERT
2025-03-18 20:36:58 | InsiderCrypto | ERROR | test_logger:22 - Esta é uma mensagem de ERROR
2025-03-18 20:36:58 | InsiderCrypto | CRITICAL | test_logger:23 - Esta é uma mensagem de CRITICAL
2025-03-18 20:36:58 | InsiderCrypto | ERROR | test_logger:29 - Erro ao dividir por zero: division by zero
Traceback (most recent call last):
  File "D:\Workspace\Projeto-Python\insider_crypto_bot\tests\test_logger.py", line 27, in test_logger
    1 / 0  # Gera uma exceção
    ~~^~~
ZeroDivisionError: division by zero
2025-03-18 20:36:58 | InsiderCrypto | ERROR | log_config:53 - [APIConnectionError] [APIConnectionError] Falha na conexão com a API (URL: https://api.example.com) | Detalhes: Timeout ao tentar conectar | Causa: Erro de rede
2025-03-18 20:36:58 | InsiderCrypto | INFO | test_logger:69 - Testando o logger retornado por get_logger
2025-03-18 23:46:33 | InsiderCrypto | DEBUG | test_logger:18 - Esta é uma mensagem de DEBUG
2025-03-18 23:46:33 | InsiderCrypto | INFO | test_logger:19 - Esta é uma mensagem de INFO
2025-03-18 23:46:33 | InsiderCrypto | WARNING | test_logger:20 - Esta é uma mensagem de WARNING
2025-03-18 23:46:33 | InsiderCrypto | ALERT | log_config:42 - Esta é uma mensagem de ALERT
2025-03-18 23:46:33 | InsiderCrypto | ERROR | test_logger:22 - Esta é uma mensagem de ERROR
2025-03-18 23:46:33 | InsiderCrypto | CRITICAL | test_logger:23 - Esta é uma mensagem de CRITICAL
2025-03-18 23:46:33 | InsiderCrypto | ERROR | test_logger:29 - Erro ao dividir por zero: division by zero
Traceback (most recent call last):
  File "D:\Workspace\Projeto-Python\insider_crypto_bot\tests\test_logger.py", line 27, in test_logger
    1 / 0  # Gera uma exceção
    ~~^~~
ZeroDivisionError: division by zero
2025-03-18 23:46:33 | InsiderCrypto | ERROR | log_config:53 - [APIConnectionError] [APIConnectionError] Falha na conexão com a API (URL: https://api.example.com) | Detalhes: Timeout ao tentar conectar | Causa: Erro de rede
2025-03-18 23:46:33 | InsiderCrypto | INFO | test_logger:69 - Testando o logger retornado por get_logger
