2025-03-19 13:43:11 | InsiderCrypto | DEBUG | test_logger:18 - Esta é uma mensagem de DEBUG
2025-03-19 13:43:11 | InsiderCrypto | INFO | test_logger:19 - Esta é uma mensagem de INFO
2025-03-19 13:43:11 | InsiderCrypto | WARNING | test_logger:20 - Esta é uma mensagem de WARNING
2025-03-19 13:43:11 | InsiderCrypto | ALERT | log_config:42 - Esta é uma mensagem de ALERT
2025-03-19 13:43:11 | InsiderCrypto | ERROR | test_logger:22 - Esta é uma mensagem de ERROR
2025-03-19 13:43:11 | InsiderCrypto | CRITICAL | test_logger:23 - Esta é uma mensagem de CRITICAL
2025-03-19 13:43:11 | InsiderCrypto | ERROR | test_logger:29 - Erro ao dividir por zero: division by zero
Traceback (most recent call last):
  File "D:\Workspace\Projeto-Python\insider_crypto_bot\tests\test_logger.py", line 27, in test_logger
    1 / 0  # Gera uma exceção
    ~~^~~
ZeroDivisionError: division by zero
2025-03-19 13:43:11 | InsiderCrypto | ERROR | log_config:53 - [APIConnectionError] [APIConnectionError] Falha na conexão com a API (URL: https://api.example.com) | Detalhes: Timeout ao tentar conectar | Causa: Erro de rede
2025-03-19 13:43:11 | InsiderCrypto | INFO | test_logger:69 - Testando o logger retornado por get_logger
2025-03-19 13:43:21 | InsiderCrypto | DEBUG | test_logger:18 - Esta é uma mensagem de DEBUG
2025-03-19 13:43:21 | InsiderCrypto | INFO | test_logger:19 - Esta é uma mensagem de INFO
2025-03-19 13:43:21 | InsiderCrypto | WARNING | test_logger:20 - Esta é uma mensagem de WARNING
2025-03-19 13:43:21 | InsiderCrypto | ALERT | log_config:42 - Esta é uma mensagem de ALERT
2025-03-19 13:43:21 | InsiderCrypto | ERROR | test_logger:22 - Esta é uma mensagem de ERROR
2025-03-19 13:43:21 | InsiderCrypto | CRITICAL | test_logger:23 - Esta é uma mensagem de CRITICAL
2025-03-19 13:43:21 | InsiderCrypto | ERROR | test_logger:29 - Erro ao dividir por zero: division by zero
Traceback (most recent call last):
  File "D:\Workspace\Projeto-Python\insider_crypto_bot\tests\test_logger.py", line 27, in test_logger
    1 / 0  # Gera uma exceção
    ~~^~~
ZeroDivisionError: division by zero
2025-03-19 13:43:21 | InsiderCrypto | ERROR | log_config:53 - [APIConnectionError] [APIConnectionError] Falha na conexão com a API (URL: https://api.example.com) | Detalhes: Timeout ao tentar conectar | Causa: Erro de rede
2025-03-19 13:43:21 | InsiderCrypto | INFO | test_logger:69 - Testando o logger retornado por get_logger
2025-03-19 13:43:42 | InsiderCrypto | DEBUG | test_logger:18 - Esta é uma mensagem de DEBUG
2025-03-19 13:43:42 | InsiderCrypto | INFO | test_logger:19 - Esta é uma mensagem de INFO
2025-03-19 13:43:42 | InsiderCrypto | WARNING | test_logger:20 - Esta é uma mensagem de WARNING
2025-03-19 14:17:26 | InsiderCrypto | DEBUG | test_logger:31 - Esta é uma mensagem de DEBUG
2025-03-19 14:17:26 | InsiderCrypto | INFO | test_logger:32 - Esta é uma mensagem de INFO
2025-03-19 14:17:26 | InsiderCrypto | WARNING | test_logger:33 - Esta é uma mensagem de WARNING
2025-03-19 14:17:26 | InsiderCrypto | ALERT | log_config:42 - Esta é uma mensagem de ALERT
2025-03-19 14:17:26 | InsiderCrypto | ERROR | test_logger:35 - Esta é uma mensagem de ERROR
2025-03-19 14:17:26 | InsiderCrypto | CRITICAL | test_logger:36 - Esta é uma mensagem de CRITICAL
2025-03-19 14:17:26 | InsiderCrypto | ERROR | test_logger:42 - Erro ao dividir por zero: division by zero
Traceback (most recent call last):
  File "D:\Workspace\Projeto-Python\insider_crypto_bot\tests\test_logger.py", line 40, in test_logger
    1 / 0  # Gera uma exceção
    ~~^~~
ZeroDivisionError: division by zero
2025-03-19 14:17:26 | InsiderCrypto | ERROR | log_config:53 - [APIConnectionError] [APIConnectionError] Falha na conexão com a API (URL: https://api.example.com) | Detalhes: Timeout ao tentar conectar | Causa: Erro de rede
2025-03-19 14:17:26 | InsiderCrypto | INFO | test_logger:82 - Testando o logger retornado por get_logger
2025-03-19 14:46:34 | InsiderCrypto | DEBUG | test_logger:31 - Esta é uma mensagem de DEBUG
2025-03-19 14:46:34 | InsiderCrypto | INFO | test_logger:32 - Esta é uma mensagem de INFO
2025-03-19 14:46:34 | InsiderCrypto | WARNING | test_logger:33 - Esta é uma mensagem de WARNING
2025-03-19 14:46:34 | InsiderCrypto | ALERT | log_config:42 - Esta é uma mensagem de ALERT
2025-03-19 14:46:34 | InsiderCrypto | ERROR | test_logger:35 - Esta é uma mensagem de ERROR
2025-03-19 14:46:34 | InsiderCrypto | CRITICAL | test_logger:36 - Esta é uma mensagem de CRITICAL
2025-03-19 14:46:34 | InsiderCrypto | ERROR | test_logger:42 - Erro ao dividir por zero: division by zero
Traceback (most recent call last):
  File "D:\Workspace\Projeto-Python\insider_crypto_bot\tests\test_logger.py", line 40, in test_logger
    1 / 0  # Gera uma exceção
    ~~^~~
ZeroDivisionError: division by zero
2025-03-19 14:46:34 | InsiderCrypto | ERROR | log_config:53 - [APIConnectionError] [APIConnectionError] Falha na conexão com a API (URL: https://api.example.com) | Detalhes: Timeout ao tentar conectar | Causa: Erro de rede
2025-03-19 14:46:34 | InsiderCrypto | INFO | test_logger:82 - Testando o logger retornado por get_logger
2025-03-19 14:52:54 | InsiderCrypto | DEBUG | test_logger:31 - Esta é uma mensagem de DEBUG
2025-03-19 14:52:54 | InsiderCrypto | INFO | test_logger:32 - Esta é uma mensagem de INFO
2025-03-19 14:52:54 | InsiderCrypto | WARNING | test_logger:33 - Esta é uma mensagem de WARNING
2025-03-19 14:52:54 | InsiderCrypto | ALERT | log_config:42 - Esta é uma mensagem de ALERT
2025-03-19 14:52:54 | InsiderCrypto | ERROR | test_logger:35 - Esta é uma mensagem de ERROR
2025-03-19 14:52:54 | InsiderCrypto | CRITICAL | test_logger:36 - Esta é uma mensagem de CRITICAL
2025-03-19 14:52:54 | InsiderCrypto | ERROR | test_logger:42 - Erro ao dividir por zero: division by zero
Traceback (most recent call last):
  File "D:\Workspace\Projeto-Python\insider_crypto_bot\tests\test_logger.py", line 40, in test_logger
    1 / 0  # Gera uma exceção
    ~~^~~
ZeroDivisionError: division by zero
2025-03-19 14:52:54 | InsiderCrypto | ERROR | log_config:53 - [APIConnectionError] [APIConnectionError] Falha na conexão com a API (URL: https://api.example.com) | Detalhes: Timeout ao tentar conectar | Causa: Erro de rede
2025-03-19 14:52:54 | InsiderCrypto | INFO | test_logger:82 - Testando o logger retornado por get_logger
2025-03-19 14:53:38 | InsiderCrypto | DEBUG | test_logger:31 - Esta é uma mensagem de DEBUG
2025-03-19 14:53:38 | InsiderCrypto | INFO | test_logger:32 - Esta é uma mensagem de INFO
2025-03-19 14:53:38 | InsiderCrypto | WARNING | test_logger:33 - Esta é uma mensagem de WARNING
2025-03-19 14:53:38 | InsiderCrypto | ALERT | log_config:42 - Esta é uma mensagem de ALERT
2025-03-19 14:53:38 | InsiderCrypto | ERROR | test_logger:35 - Esta é uma mensagem de ERROR
2025-03-19 14:53:38 | InsiderCrypto | CRITICAL | test_logger:36 - Esta é uma mensagem de CRITICAL
2025-03-19 14:53:38 | InsiderCrypto | ERROR | test_logger:42 - Erro ao dividir por zero: division by zero
Traceback (most recent call last):
  File "D:\Workspace\Projeto-Python\insider_crypto_bot\tests\test_logger.py", line 40, in test_logger
    1 / 0  # Gera uma exceção
    ~~^~~
ZeroDivisionError: division by zero
2025-03-19 14:53:38 | InsiderCrypto | ERROR | log_config:53 - [APIConnectionError] [APIConnectionError] Falha na conexão com a API (URL: https://api.example.com) | Detalhes: Timeout ao tentar conectar | Causa: Erro de rede
2025-03-19 14:53:38 | InsiderCrypto | INFO | test_logger:82 - Testando o logger retornado por get_logger
2025-03-19 14:53:58 | InsiderCrypto | DEBUG | test_logger:31 - Esta é uma mensagem de DEBUG
2025-03-19 14:53:58 | InsiderCrypto | INFO | test_logger:32 - Esta é uma mensagem de INFO
2025-03-19 14:53:58 | InsiderCrypto | WARNING | test_logger:33 - Esta é uma mensagem de WARNING
2025-03-19 14:53:58 | InsiderCrypto | ALERT | log_config:42 - Esta é uma mensagem de ALERT
2025-03-19 14:53:58 | InsiderCrypto | ERROR | test_logger:35 - Esta é uma mensagem de ERROR
2025-03-19 14:53:58 | InsiderCrypto | CRITICAL | test_logger:36 - Esta é uma mensagem de CRITICAL
2025-03-19 14:53:58 | InsiderCrypto | ERROR | test_logger:42 - Erro ao dividir por zero: division by zero
Traceback (most recent call last):
  File "D:\Workspace\Projeto-Python\insider_crypto_bot\tests\test_logger.py", line 40, in test_logger
    1 / 0  # Gera uma exceção
    ~~^~~
ZeroDivisionError: division by zero
2025-03-19 14:53:58 | InsiderCrypto | ERROR | log_config:53 - [APIConnectionError] [APIConnectionError] Falha na conexão com a API (URL: https://api.example.com) | Detalhes: Timeout ao tentar conectar | Causa: Erro de rede
2025-03-19 14:53:58 | InsiderCrypto | INFO | test_logger:82 - Testando o logger retornado por get_logger
